Last login: Fri Sep 11 14:03:44 on ttys000
amber@MacBook-Pro-van-Amber ~ % git remote add origin
fatal: not a git repository (or any of the parent directories): .git
amber@MacBook-Pro-van-Amber ~ % git remote add origin https://github.com/AmberRosanne/PythonAchievements
fatal: not a git repository (or any of the parent directories): .git
amber@MacBook-Pro-van-Amber ~ % cd documents
amber@MacBook-Pro-van-Amber documents % cd school
amber@MacBook-Pro-van-Amber school % cd mediadeveloper
amber@MacBook-Pro-van-Amber mediadeveloper % git remote add origin https://github.com/AmberRosanne/PythonAchievements
fatal: not a git repository (or any of the parent directories): .git
amber@MacBook-Pro-van-Amber mediadeveloper % cd PythonAchievement   
cd: no such file or directory: PythonAchievement
amber@MacBook-Pro-van-Amber mediadeveloper % cd PythonAchievements
amber@MacBook-Pro-van-Amber PythonAchievements % git remote add origin https://github.com/AmberRosanne/PythonAchievements
amber@MacBook-Pro-van-Amber PythonAchievements % git push -u origin master
Username for 'https://github.com': amberrosanne
Password for 'https://amberrosanne@github.com': 
To https://github.com/AmberRosanne/PythonAchievements
 ! [rejected]        master -> master (fetch first)
error: failed to push some refs to 'https://github.com/AmberRosanne/PythonAchievements'
hint: Updates were rejected because the remote contains work that you do
hint: not have locally. This is usually caused by another repository pushing
hint: to the same ref. You may want to first integrate the remote changes
hint: (e.g., 'git pull ...') before pushing again.
hint: See the 'Note about fast-forwards' in 'git push --help' for details.
amber@MacBook-Pro-van-Amber PythonAchievements % git push -u origin master
To https://github.com/AmberRosanne/PythonAchievements
 ! [rejected]        master -> master (fetch first)
error: failed to push some refs to 'https://github.com/AmberRosanne/PythonAchievements'
hint: Updates were rejected because the remote contains work that you do
hint: not have locally. This is usually caused by another repository pushing
hint: to the same ref. You may want to first integrate the remote changes
hint: (e.g., 'git pull ...') before pushing again.
hint: See the 'Note about fast-forwards' in 'git push --help' for details.
amber@MacBook-Pro-van-Amber PythonAchievements % 
